using FluentAssertions;
using Xunit;

namespace Meziantou.Framework.Tests;

public sealed class TaskExtensionsTests
{
    [Fact]
    public void ForgetTest_SuccessfullyCompleted()
    {
        var task = Task.FromResult(0);
        task.Forget(); // Should not throw exception
    }

    [Fact]
    public void ForgetTest_Faulted()
    {
        var task = Task.FromException(new InvalidOperationException(""));
        task.Forget(); // Should not throw exception
    }

    [Fact]
    public void ForgetTest_Canceled()
    {
        using var cts = new CancellationTokenSource();
        cts.Cancel();
        var task = Task.FromCanceled(cts.Token);
        task.Forget(); // Should not throw exception
    }

    [Fact]
    public async Task WhenAll()
    {
        var (a, b) = await (Task.FromResult(0), Task.FromResult("test"));

        a.Should().Be(0);
        b.Should().Be("test");
    }

    [Fact]
    public async Task WhenAll_NonGenericTask()
    {
        await (Task.CompletedTask, Task.CompletedTask);
    }

    [Fact]
    [SuppressMessage("Reliability", "CA2012:Use ValueTasks correctly", Justification = "For testing purpose")]
    public async Task WhenAll_ValueTask()
    {
        var (a, b) = await (ValueTask.FromResult(0), ValueTask.FromResult("test"));

        a.Should().Be(0);
        b.Should().Be("test");
    }

    [Fact]
    [SuppressMessage("Reliability", "CA2012:Use ValueTasks correctly", Justification = "For testing purpose")]
    public async Task WhenAll_ValueTask_Exception()
    {
        try
        {
            await (ValueTask.FromResult(0), ValueTask.FromException<string>(new InvalidOperationException("test")));
            false.Should().BeTrue("Should not reach this line");
        }
        catch (AggregateException ex)
        {
            ex.Message.Should().Be("One or more errors occurred. (test)");
        }
    }
}
